{"metadata":{"kernelspec":{"language":"python","display_name":"Python 3","name":"python3"},"language_info":{"name":"python","version":"3.10.13","mimetype":"text/x-python","codemirror_mode":{"name":"ipython","version":3},"pygments_lexer":"ipython3","nbconvert_exporter":"python","file_extension":".py"},"kaggle":{"accelerator":"gpu","dataSources":[{"sourceId":2448367,"sourceType":"datasetVersion","datasetId":1481754}],"dockerImageVersionId":30698,"isInternetEnabled":true,"language":"python","sourceType":"notebook","isGpuEnabled":true}},"nbformat_minor":4,"nbformat":4,"cells":[{"cell_type":"code","source":"# This Python 3 environment comes with many helpful analytics libraries installed\n# It is defined by the kaggle/python Docker image: https://github.com/kaggle/docker-python\n# For example, here's several helpful packages to load\n\nimport numpy as np # linear algebra\nimport pandas as pd # data processing, CSV file I/O (e.g. pd.read_csv)\n\n# Input data files are available in the read-only \"../input/\" directory\n# For example, running this (by clicking run or pressing Shift+Enter) will list all files under the input directory\n\nimport os\nfor dirname, _, filenames in os.walk('/kaggle/input'):\n    for filename in filenames:\n        print(os.path.join(dirname, filename))\n\n# You can write up to 20GB to the current directory (/kaggle/working/) that gets preserved as output when you create a version using \"Save & Run All\" \n# You can also write temporary files to /kaggle/temp/, but they won't be saved outside of the current session","metadata":{"_uuid":"8f2839f25d086af736a60e9eeb907d3b93b6e0e5","_cell_guid":"b1076dfc-b9ad-4769-8c92-a6c4dae69d19","execution":{"iopub.status.busy":"2024-05-31T17:25:21.533324Z","iopub.execute_input":"2024-05-31T17:25:21.533652Z","iopub.status.idle":"2024-05-31T17:25:22.450239Z","shell.execute_reply.started":"2024-05-31T17:25:21.533620Z","shell.execute_reply":"2024-05-31T17:25:22.449240Z"},"trusted":true},"execution_count":1,"outputs":[]},{"cell_type":"code","source":"# Importing module and initializing setup\nfrom pycaret.classification import *\nclf1 = setup(data = diabetes, target = 'Class variable')\n\n# comparing all models\ncompare_models()","metadata":{"execution":{"iopub.status.busy":"2024-05-31T18:08:41.551975Z","iopub.execute_input":"2024-05-31T18:08:41.552346Z","iopub.status.idle":"2024-05-31T18:08:42.467530Z","shell.execute_reply.started":"2024-05-31T18:08:41.552318Z","shell.execute_reply":"2024-05-31T18:08:42.466389Z"},"trusted":true},"execution_count":11,"outputs":[{"name":"stdout","text":"Unexpected exception formatting exception. Falling back to standard exception\n","output_type":"stream"},{"name":"stderr","text":"Traceback (most recent call last):\n  File \"/opt/conda/lib/python3.10/site-packages/IPython/core/interactiveshell.py\", line 3553, in run_code\n    exec(code_obj, self.user_global_ns, self.user_ns)\n  File \"/tmp/ipykernel_35/283153459.py\", line 2, in <module>\n    from pycaret.classification import *\n  File \"/opt/conda/lib/python3.10/site-packages/pycaret/classification/__init__.py\", line 1, in <module>\n    from pycaret.classification.functional import (\n  File \"/opt/conda/lib/python3.10/site-packages/pycaret/classification/functional.py\", line 8, in <module>\n    from pycaret.classification.oop import ClassificationExperiment\n  File \"/opt/conda/lib/python3.10/site-packages/pycaret/classification/oop.py\", line 11, in <module>\n    import plotly.express as px\n  File \"/opt/conda/lib/python3.10/site-packages/plotly/express/__init__.py\", line 14, in <module>\n    from ._imshow import imshow\n  File \"/opt/conda/lib/python3.10/site-packages/plotly/express/_imshow.py\", line 11, in <module>\n    import xarray\n  File \"/opt/conda/lib/python3.10/site-packages/xarray/__init__.py\", line 3, in <module>\n    from xarray import testing, tutorial\n  File \"/opt/conda/lib/python3.10/site-packages/xarray/testing/__init__.py\", line 1, in <module>\n    from xarray.testing.assertions import (  # noqa: F401\n  File \"/opt/conda/lib/python3.10/site-packages/xarray/testing/assertions.py\", line 11, in <module>\n    from xarray.core import duck_array_ops, formatting, utils\n  File \"/opt/conda/lib/python3.10/site-packages/xarray/core/duck_array_ops.py\", line 36, in <module>\n    from xarray.core import dask_array_ops, dtypes, nputils\n  File \"/opt/conda/lib/python3.10/site-packages/xarray/core/dask_array_ops.py\", line 3, in <module>\n    from xarray.core import dtypes, nputils\n  File \"/opt/conda/lib/python3.10/site-packages/xarray/core/nputils.py\", line 14, in <module>\n    if module_available(\"numpy\", minversion=\"2.0.0.dev0\"):\n  File \"/opt/conda/lib/python3.10/site-packages/xarray/namedarray/utils.py\", line 62, in module_available\n    return Version(version) >= Version(minversion)\n  File \"/opt/conda/lib/python3.10/site-packages/packaging/version.py\", line 264, in __init__\nTypeError: expected string or bytes-like object\n\nDuring handling of the above exception, another exception occurred:\n\nTraceback (most recent call last):\n  File \"/opt/conda/lib/python3.10/site-packages/IPython/core/interactiveshell.py\", line 2144, in showtraceback\n    stb = self.InteractiveTB.structured_traceback(\n  File \"/opt/conda/lib/python3.10/site-packages/IPython/core/ultratb.py\", line 1435, in structured_traceback\n    return FormattedTB.structured_traceback(\n  File \"/opt/conda/lib/python3.10/site-packages/IPython/core/ultratb.py\", line 1326, in structured_traceback\n    return VerboseTB.structured_traceback(\n  File \"/opt/conda/lib/python3.10/site-packages/IPython/core/ultratb.py\", line 1173, in structured_traceback\n    formatted_exception = self.format_exception_as_a_whole(etype, evalue, etb, number_of_lines_of_context,\n  File \"/opt/conda/lib/python3.10/site-packages/IPython/core/ultratb.py\", line 1088, in format_exception_as_a_whole\n    frames.append(self.format_record(record))\n  File \"/opt/conda/lib/python3.10/site-packages/IPython/core/ultratb.py\", line 970, in format_record\n    frame_info.lines, Colors, self.has_colors, lvals\n  File \"/opt/conda/lib/python3.10/site-packages/IPython/core/ultratb.py\", line 792, in lines\n    return self._sd.lines\n  File \"/opt/conda/lib/python3.10/site-packages/stack_data/utils.py\", line 145, in cached_property_wrapper\n    value = obj.__dict__[self.func.__name__] = self.func(obj)\n  File \"/opt/conda/lib/python3.10/site-packages/stack_data/core.py\", line 734, in lines\n    pieces = self.included_pieces\n  File \"/opt/conda/lib/python3.10/site-packages/stack_data/utils.py\", line 145, in cached_property_wrapper\n    value = obj.__dict__[self.func.__name__] = self.func(obj)\n  File \"/opt/conda/lib/python3.10/site-packages/stack_data/core.py\", line 681, in included_pieces\n    pos = scope_pieces.index(self.executing_piece)\n  File \"/opt/conda/lib/python3.10/site-packages/stack_data/utils.py\", line 145, in cached_property_wrapper\n    value = obj.__dict__[self.func.__name__] = self.func(obj)\n  File \"/opt/conda/lib/python3.10/site-packages/stack_data/core.py\", line 660, in executing_piece\n    return only(\n  File \"/opt/conda/lib/python3.10/site-packages/executing/executing.py\", line 116, in only\n    raise NotOneValueFound('Expected one value, found 0')\nexecuting.executing.NotOneValueFound: Expected one value, found 0\n","output_type":"stream"}]}]}